Workbook
Name UTSANG: #REF!

Sheet UTPALAA
A1: ENVIRONMENT AND SAFETY EVALUATION
A3: Project: | C3: UTPALAA | D3: Period | E3: FEBRUARY | H3: 2026
F4: Status
A5: Overall Score: | C5: =C171 -> 0.67030361 | D5: E.A.S.E Category: | H5: =H171 -> BELOW AVERAGE
A7: Topic | B7: Sl. No. | C7: Evaluation Elements | D7: Status | E7: Assessment Value | F7: Score Applicable | G7: Marks Obtained | H7: Topic Percentage | I7: Gradation
A8: General Safety | B8: 1 | C8: Are Safety meetings conducted across the table at least once monthly and minutes communicated? | D8: Yes | E8: 3 | F8: =IF(D8="","",IF(D8="Yes",E8,IF(D8="Tending to Yes",E8,IF(D8="Tending to No",E8,IF(D8="No",E8,))))) -> 3 | G8: =IF(E8="NA","NA",IF(D8="Yes",E8,IF(D8="Tending to yes",E8/2,IF(D8="Tending to No",F8/4,IF(D8="No",0,IF(D8="","Input Status")))))) -> 3 | H8: =IF(SUMPRODUCT(F8:F25)=0,"NA",(SUMPRODUCT(G8:G25)/SUMPRODUCT(F8:F25))) -> 0.52941176 | I8: =IF(H8=" "," ",IF(H8=FQ8,"Not Applicable",IF(H8>89%,"EXCELLENT",IF(H8<60%,"BELOW AVERAGE",IF(H8<75%,"AVERAGE",IF(H8>74%,"GOOD")))))) -> BELOW AVERAGE | Y8: UTALIKA | Z8: JANUARY | AA8: 2025
B9: =+B8+1 -> 2 | C9: Are Safety tool-box talks conducted daily and records maintained? | D9: Yes | E9: 3 | F9: =IF(D9="","",IF(D9="Yes",E9,IF(D9="Tending to Yes",E9,IF(D9="Tending to No",E9,IF(D9="No",E9,))))) -> 3 | G9: =IF(E9="NA","NA",IF(D9="Yes",E9,IF(D9="Tending to yes",E9/2,IF(D9="Tending to No",F9/4,IF(D9="No",0,IF(D9="","Input Status")))))) -> 3 | Y9: USSHAR | Z9: FEBRUARY | AA9: 2026
B10: =+B9+1 -> 3 | C10: Are Safety induction provided to all new joinings and records maintained? | D10: Yes | E10: 3 | F10: =IF(D10="","",IF(D10="Yes",E10,IF(D10="Tending to Yes",E10,IF(D10="Tending to No",E10,IF(D10="No",E10,))))) -> 3 | G10: =IF(E10="NA","NA",IF(D10="Yes",E10,IF(D10="Tending to yes",E10/2,IF(D10="Tending to No",F10/4,IF(D10="No",0,IF(D10="","Input Status")))))) -> 3 | Y10: UTSODHARA | Z10: MARCH | AA10: 2027
B11: =+B10+1 -> 4 | C11: Is pre-employment medical checkup conducted for all newly joined workers? | D11: Yes | E11: 3 | F11: =IF(D11="","",IF(D11="Yes",E11,IF(D11="Tending to Yes",E11,IF(D11="Tending to No",E11,IF(D11="No",E11,))))) -> 3 | G11: =IF(E11="NA","NA",IF(D11="Yes",E11,IF(D11="Tending to yes",E11/2,IF(D11="Tending to No",F11/4,IF(D11="No",0,IF(D11="","Input Status")))))) -> 3 | Y11: UTPALAA | Z11: APRIL | AA11: 2028
B12: =+B11+1 -> 5 | C12: Is work beside water bodies being conducted without any risk whatsoever? | E12: NA | F12: =IF(D12="","",IF(D12="Yes",E12,IF(D12="Tending to Yes",E12,IF(D12="Tending to No",E12,IF(D12="No",E12,))))) | G12: =IF(E12="NA","NA",IF(D12="Yes",E12,IF(D12="Tending to yes",E12/2,IF(D12="Tending to No",F12/4,IF(D12="No",0,IF(D12="","Input Status")))))) -> NA | Y12: UDYAAT | Z12: MAY | AA12: 2029
B13: =+B12+1 -> 6 | C13: Are there display of Safety posters and messages in dimensions 3 feet by 4 feet? Minimum 20 numbers | D13: Yes | E13: 3 | F13: =IF(D13="","",IF(D13="Yes",E13,IF(D13="Tending to Yes",E13,IF(D13="Tending to No",E13,IF(D13="No",E13,))))) -> 3 | G13: =IF(E13="NA","NA",IF(D13="Yes",E13,IF(D13="Tending to yes",E13/2,IF(D13="Tending to No",F13/4,IF(D13="No",0,IF(D13="","Input Status")))))) -> 3 | Y13: ESBT | Z13: JUNE | AA13: 2030
B14: =+B13+1 -> 7 | C14: Are there display of Safety signage and warning/ caution signs in all the relevant areas? | D14: Yes | E14: 3 | F14: =IF(D14="","",IF(D14="Yes",E14,IF(D14="Tending to Yes",E14,IF(D14="Tending to No",E14,IF(D14="No",E14,))))) -> 3 | G14: =IF(E14="NA","NA",IF(D14="Yes",E14,IF(D14="Tending to yes",E14/2,IF(D14="Tending to No",F14/4,IF(D14="No",0,IF(D14="","Input Status")))))) -> 3 | Y14: URVISHA | Z14: JULY | AA14: 2031
B15: =+B14+1 -> 8 | C15: Are there display of Emergency contact numbers at prominent places in work area easily visible to the eye? | D15: Yes | E15: 3 | F15: =IF(D15="","",IF(D15="Yes",E15,IF(D15="Tending to Yes",E15,IF(D15="Tending to No",E15,IF(D15="No",E15,))))) -> 3 | G15: =IF(E15="NA","NA",IF(D15="Yes",E15,IF(D15="Tending to yes",E15/2,IF(D15="Tending to No",F15/4,IF(D15="No",0,IF(D15="","Input Status")))))) -> 3 | Y15: THE PARK | Z15: AUGUST | AA15: 2032
B16: =+B15+1 -> 9 | C16: Are Near Misses reported? | D16: No | E16: 3 | F16: =IF(D16="","",IF(D16="Yes",E16,IF(D16="Tending to Yes",E16,IF(D16="Tending to No",E16,IF(D16="No",E16,))))) -> 3 | G16: =IF(E16="NA","NA",IF(D16="Yes",E16,IF(D16="Tending to yes",E16/2,IF(D16="Tending to No",F16/4,IF(D16="No",0,IF(D16="","Input Status")))))) -> 0 | Z16: SEPTEMBER | AA16: 2033
B17: =+B16+1 -> 10 | C17: Are approach roads safe for vehicle and pedestrian movement? | D17: Tending to Yes | E17: 3 | F17: =IF(D17="","",IF(D17="Yes",E17,IF(D17="Tending to Yes",E17,IF(D17="Tending to No",E17,IF(D17="No",E17,))))) -> 3 | G17: =IF(E17="NA","NA",IF(D17="Yes",E17,IF(D17="Tending to yes",E17/2,IF(D17="Tending to No",F17/4,IF(D17="No",0,IF(D17="","Input Status")))))) -> 1.5 | Z17: OCTOBER | AA17: 2034
B18: =+B17+1 -> 11 | C18: Are there enough resting sheds for the labours inside the work zone? | D18: No | E18: 3 | F18: =IF(D18="","",IF(D18="Yes",E18,IF(D18="Tending to Yes",E18,IF(D18="Tending to No",E18,IF(D18="No",E18,))))) -> 3 | G18: =IF(E18="NA","NA",IF(D18="Yes",E18,IF(D18="Tending to yes",E18/2,IF(D18="Tending to No",F18/4,IF(D18="No",0,IF(D18="","Input Status")))))) -> 0 | Z18: NOVEMBER | AA18: 2035
B19: =+B18+1 -> 12 | C19: Are contractors served written warnings on repetitive / pending observations? | D19: No | E19: 3 | F19: =IF(D19="","",IF(D19="Yes",E19,IF(D19="Tending to Yes",E19,IF(D19="Tending to No",E19,IF(D19="No",E19,))))) -> 3 | G19: =IF(E19="NA","NA",IF(D19="Yes",E19,IF(D19="Tending to yes",E19/2,IF(D19="Tending to No",F19/4,IF(D19="No",0,IF(D19="","Input Status")))))) -> 0 | Z19: DECEMBER | AA19: 2036
B20: =+B19+1 -> 13 | C20: Do the execution team members conduct safety observations (5 observations/ per day/ per person)? | D20: No | E20: 3 | F20: =IF(D20="","",IF(D20="Yes",E20,IF(D20="Tending to Yes",E20,IF(D20="Tending to No",E20,IF(D20="No",E20,))))) -> 3 | G20: =IF(E20="NA","NA",IF(D20="Yes",E20,IF(D20="Tending to yes",E20/2,IF(D20="Tending to No",F20/4,IF(D20="No",0,IF(D20="","Input Status")))))) -> 0 | AA20: 2037
B21: =+B20+1 -> 14 | C21: Is percentage of rectification more than 90%? | D21: No | E21: 3 | F21: =IF(D21="","",IF(D21="Yes",E21,IF(D21="Tending to Yes",E21,IF(D21="Tending to No",E21,IF(D21="No",E21,))))) -> 3 | G21: =IF(E21="NA","NA",IF(D21="Yes",E21,IF(D21="Tending to yes",E21/2,IF(D21="Tending to No",F21/4,IF(D21="No",0,IF(D21="","Input Status")))))) -> 0 | AA21: 2038
B22: =+B21+1 -> 15 | C22: Do all the unsafe jobs receive a Job Discontinuation/stoppage/penalty notice from site management? | D22: Yes | E22: 3 | F22: =IF(D22="","",IF(D22="Yes",E22,IF(D22="Tending to Yes",E22,IF(D22="Tending to No",E22,IF(D22="No",E22,))))) -> 3 | G22: =IF(E22="NA","NA",IF(D22="Yes",E22,IF(D22="Tending to yes",E22/2,IF(D22="Tending to No",F22/4,IF(D22="No",0,IF(D22="","Input Status")))))) -> 3 | AA22: 2039
B23: =+B22+1 -> 16 | C23: Is the site free of High Risk (fatality potential) observations? | D23: No | E23: 3 | F23: =IF(D23="","",IF(D23="Yes",E23,IF(D23="Tending to Yes",E23,IF(D23="Tending to No",E23,IF(D23="No",E23,))))) -> 3 | G23: =IF(E23="NA","NA",IF(D23="Yes",E23,IF(D23="Tending to yes",E23/2,IF(D23="Tending to No",F23/4,IF(D23="No",0,IF(D23="","Input Status")))))) -> 0 | AA23: 2040
B24: =+B23+1 -> 17 | C24: Is there minimum 1 mock drill conducted per month and the documents are available? | D24: No | E24: 3 | F24: =IF(D24="","",IF(D24="Yes",E24,IF(D24="Tending to Yes",E24,IF(D24="Tending to No",E24,IF(D24="No",E24,))))) -> 3 | G24: =IF(E24="NA","NA",IF(D24="Yes",E24,IF(D24="Tending to yes",E24/2,IF(D24="Tending to No",F24/4,IF(D24="No",0,IF(D24="","Input Status")))))) -> 0
B25: =+B24+1 -> 18 | C25: Is there minimum 1 SHE campaigns orgnised such as safety stand-downs, demonstrations, etc. per month? | D25: Tending to Yes | E25: 3 | F25: =IF(D25="","",IF(D25="Yes",E25,IF(D25="Tending to Yes",E25,IF(D25="Tending to No",E25,IF(D25="No",E25,))))) -> 3 | G25: =IF(E25="NA","NA",IF(D25="Yes",E25,IF(D25="Tending to yes",E25/2,IF(D25="Tending to No",F25/4,IF(D25="No",0,IF(D25="","Input Status")))))) -> 1.5
A26: Housekeeping | B26: =+B25+1 -> 19 | C26: Is the site neat and clean? | D26: Tending to Yes | E26: 4 | F26: =IF(D26="","",IF(D26="Yes",E26,IF(D26="Tending to Yes",E26,IF(D26="Tending to No",E26,IF(D26="No",E26,))))) -> 4 | G26: =IF(E26="NA","NA",IF(D26="Yes",E26,IF(D26="Tending to yes",E26/2,IF(D26="Tending to No",F26/4,IF(D26="No",0,IF(D26="","Input Status")))))) -> 2 | H26: =IF(SUMPRODUCT(F26:F41)=0,"NA",(SUMPRODUCT(G26:G41)/SUMPRODUCT(F26:F41))) -> 0.45 | I26: =IF(H26="NA","NA",IF(H26>90%,"EXCELLENT",IF(H26<60%,"BELOW AVERAGE",IF(H26<75%,"AVERAGE",IF(H26>74%,"GOOD"))))) -> BELOW AVERAGE
B27: =+B26+1 -> 20 | C27: Are all access/ egress routes, pathways, staircases etc. free from risk of slip, trip & fall hazards | D27: Tending to Yes | E27: 4 | F27: =IF(D27="","",IF(D27="Yes",E27,IF(D27="Tending to Yes",E27,IF(D27="Tending to No",E27,IF(D27="No",E27,))))) -> 4 | G27: =IF(E27="NA","NA",IF(D27="Yes",E27,IF(D27="Tending to yes",E27/2,IF(D27="Tending to No",F27/4,IF(D27="No",0,IF(D27="","Input Status")))))) -> 2
B28: =+B27+1 -> 21 | C28: Is the site free from signs of oil spillage and other agents that can pollute the top soil? | D28: Tending to Yes | E28: 4 | F28: =IF(D28="","",IF(D28="Yes",E28,IF(D28="Tending to Yes",E28,IF(D28="Tending to No",E28,IF(D28="No",E28,))))) -> 4 | G28: =IF(E28="NA","NA",IF(D28="Yes",E28,IF(D28="Tending to yes",E28/2,IF(D28="Tending to No",F28/4,IF(D28="No",0,IF(D28="","Input Status")))))) -> 2
B29: =+B28+1 -> 22 | C29: Are walking paths for pedestrians marked and separated from vehical routes? | D29: No | E29: 4 | F29: =IF(D29="","",IF(D29="Yes",E29,IF(D29="Tending to Yes",E29,IF(D29="Tending to No",E29,IF(D29="No",E29,))))) -> 4 | G29: =IF(E29="NA","NA",IF(D29="Yes",E29,IF(D29="Tending to yes",E29/2,IF(D29="Tending to No",F29/4,IF(D29="No",0,IF(D29="","Input Status")))))) -> 0
B30: =+B29+1 -> 23 | C30: Are construction materials, earth, etc. stacked and stored that they do not roll or collapse? | D30: Yes | E30: 4 | F30: =IF(D30="","",IF(D30="Yes",E30,IF(D30="Tending to Yes",E30,IF(D30="Tending to No",E30,IF(D30="No",E30,))))) -> 4 | G30: =IF(E30="NA","NA",IF(D30="Yes",E30,IF(D30="Tending to yes",E30/2,IF(D30="Tending to No",F30/4,IF(D30="No",0,IF(D30="","Input Status")))))) -> 4
B31: =+B30+1 -> 24 | C31: Is the average illumination level of the entire project site more than equal to 150 Lux? | D31: Tending to Yes | E31: 4 | F31: =IF(D31="","",IF(D31="Yes",E31,IF(D31="Tending to Yes",E31,IF(D31="Tending to No",E31,IF(D31="No",E31,))))) -> 4 | G31: =IF(E31="NA","NA",IF(D31="Yes",E31,IF(D31="Tending to yes",E31/2,IF(D31="Tending to No",F31/4,IF(D31="No",0,IF(D31="","Input Status")))))) -> 2
B32: =+B31+1 -> 25 | C32: Are chemicals and oils stored as per recommendations in the MSDS? | D32: No | E32: 4 | F32: =IF(D32="","",IF(D32="Yes",E32,IF(D32="Tending to Yes",E32,IF(D32="Tending to No",E32,IF(D32="No",E32,))))) -> 4 | G32: =IF(E32="NA","NA",IF(D32="Yes",E32,IF(D32="Tending to yes",E32/2,IF(D32="Tending to No",F32/4,IF(D32="No",0,IF(D32="","Input Status")))))) -> 0
B33: =+B32+1 -> 26 | C33: Is the site free from rods protruding from ground or sharp objects along height of a person's face? | D33: Tending to Yes | E33: 4 | F33: =IF(D33="","",IF(D33="Yes",E33,IF(D33="Tending to Yes",E33,IF(D33="Tending to No",E33,IF(D33="No",E33,))))) -> 4 | G33: =IF(E33="NA","NA",IF(D33="Yes",E33,IF(D33="Tending to yes",E33/2,IF(D33="Tending to No",F33/4,IF(D33="No",0,IF(D33="","Input Status")))))) -> 2
B34: =+B33+1 -> 27 | C34: Are debris disposal chutes available to dispose debris from elevated floors? | E34: NA | F34: =IF(D34="","",IF(D34="Yes",E34,IF(D34="Tending to Yes",E34,IF(D34="Tending to No",E34,IF(D34="No",E34,))))) | G34: =IF(E34="NA","NA",IF(D34="Yes",E34,IF(D34="Tending to yes",E34/2,IF(D34="Tending to No",F34/4,IF(D34="No",0,IF(D34="","Input Status")))))) -> NA
B35: =+B34+1 -> 28 | C35: Is site free from water stagnation? | D35: No | E35: 4 | F35: =IF(D35="","",IF(D35="Yes",E35,IF(D35="Tending to Yes",E35,IF(D35="Tending to No",E35,IF(D35="No",E35,))))) -> 4 | G35: =IF(E35="NA","NA",IF(D35="Yes",E35,IF(D35="Tending to yes",E35/2,IF(D35="Tending to No",F35/4,IF(D35="No",0,IF(D35="","Input Status")))))) -> 0
B36: =+B35+1 -> 29 | C36: Are all job locations in the project easily approachable by all? | D36: Yes | E36: 4 | F36: =IF(D36="","",IF(D36="Yes",E36,IF(D36="Tending to Yes",E36,IF(D36="Tending to No",E36,IF(D36="No",E36,))))) -> 4 | G36: =IF(E36="NA","NA",IF(D36="Yes",E36,IF(D36="Tending to yes",E36/2,IF(D36="Tending to No",F36/4,IF(D36="No",0,IF(D36="","Input Status")))))) -> 4
B37: =+B36+1 -> 30 | C37: Is there a smoking booth available and being used? No one found smoking in the work place. | D37: No | E37: 4 | F37: =IF(D37="","",IF(D37="Yes",E37,IF(D37="Tending to Yes",E37,IF(D37="Tending to No",E37,IF(D37="No",E37,))))) -> 4 | G37: =IF(E37="NA","NA",IF(D37="Yes",E37,IF(D37="Tending to yes",E37/2,IF(D37="Tending to No",F37/4,IF(D37="No",0,IF(D37="","Input Status")))))) -> 0
B38: =+B37+1 -> 31 | C38: Is scrap/debris kept separately and safely in designated/ demarcated areas | D38: Yes | E38: 4 | F38: =IF(D38="","",IF(D38="Yes",E38,IF(D38="Tending to Yes",E38,IF(D38="Tending to No",E38,IF(D38="No",E38,))))) -> 4 | G38: =IF(E38="NA","NA",IF(D38="Yes",E38,IF(D38="Tending to yes",E38/2,IF(D38="Tending to No",F38/4,IF(D38="No",0,IF(D38="","Input Status")))))) -> 4
B39: =+B38+1 -> 32 | C39: Are deshuttered materials stacked neatly in an uncluttered manner? | D39: Tending to Yes | E39: 4 | F39: =IF(D39="","",IF(D39="Yes",E39,IF(D39="Tending to Yes",E39,IF(D39="Tending to No",E39,IF(D39="No",E39,))))) -> 4 | G39: =IF(E39="NA","NA",IF(D39="Yes",E39,IF(D39="Tending to yes",E39/2,IF(D39="Tending to No",F39/4,IF(D39="No",0,IF(D39="","Input Status")))))) -> 2
B40: =+B39+1 -> 33 | C40: Are defective materials segregated from sound materials? | D40: Tending to No | E40: 4 | F40: =IF(D40="","",IF(D40="Yes",E40,IF(D40="Tending to Yes",E40,IF(D40="Tending to No",E40,IF(D40="No",E40,))))) -> 4 | G40: =IF(E40="NA","NA",IF(D40="Yes",E40,IF(D40="Tending to yes",E40/2,IF(D40="Tending to No",F40/4,IF(D40="No",0,IF(D40="","Input Status")))))) -> 1
B41: =+B40+1 -> 34 | C41: Are Flammable materials stored separately? | D41: Tending to Yes | E41: 4 | F41: =IF(D41="","",IF(D41="Yes",E41,IF(D41="Tending to Yes",E41,IF(D41="Tending to No",E41,IF(D41="No",E41,))))) -> 4 | G41: =IF(E41="NA","NA",IF(D41="Yes",E41,IF(D41="Tending to yes",E41/2,IF(D41="Tending to No",F41/4,IF(D41="No",0,IF(D41="","Input Status")))))) -> 2
A42: Personal Protective Equipment and work apparels | B42: =+B41+1 -> 35 | C42: Is there 100% implementation of safety helmet with chin-straps? | D42: Tending to Yes | E42: 5 | F42: =IF(D42="","",IF(D42="Yes",E42,IF(D42="Tending to Yes",E42,IF(D42="Tending to No",E42,IF(D42="No",E42,))))) -> 5 | G42: =IF(E42="NA","NA",IF(D42="Yes",E42,IF(D42="Tending to yes",E42/2,IF(D42="Tending to No",F42/4,IF(D42="No",0,IF(D42="","Input Status")))))) -> 2.5 | H42: =IF(SUMPRODUCT(F42:F48)=0,"NA",(SUMPRODUCT(G42:G48)/SUMPRODUCT(F42:F48))) -> 0.73214286 | I42: =IF(H42="NA","NA",IF(H42>90%,"EXCELLENT",IF(H42<60%,"BELOW AVERAGE",IF(H42<75%,"AVERAGE",IF(H42>74%,"GOOD"))))) -> AVERAGE
...

Sheet Graphs 
C4: Topic average-All sites | P4: Q-4 (24-25) | Q4: Q-3 (24-25) | R4: Q-2 (24-25) | S4: Q-1 (25-26)
A5: General Safety | B5: =UTPALAA!D176 -> 0.52941176 | C5: =AVERAGE(B5) -> 0.52941176 | O5: General Safety | P5: 0.82 | Q5: 0.81 | R5: 0.79 | S5: 0.82
A6: Housekeeping | B6: =UTPALAA!D177 -> 0.45 | C6: =AVERAGE(B6) -> 0.45 | O6: Housekeeping | P6: 0.84 | Q6: 0.86 | R6: 0.84 | S6: 0.86
A7: Personal Protective Equipment and work apparels | B7: =UTPALAA!D178 -> 0.73214286 | C7: =AVERAGE(B7) -> 0.73214286 | O7: Personal Protective Equipment and work apparels | P7: 0.79 | Q7: 0.82 | R7: 0.74 | S7: 0.78
A8: Work at Height | B8: =UTPALAA!D179 -> 0.63888889 | C8: =AVERAGE(B8) -> 0.63888889 | O8: Work at Height | P8: 0.79 | Q8: 0.78 | R8: 0.76 | S8: 0.8
A9: Electrical | B9: =UTPALAA!D180 -> 0.63888889 | C9: =AVERAGE(B9) -> 0.63888889 | O9: Electrical | P9: 0.87 | Q9: 0.88 | R9: 0.86 | S9: 0.86
A10: Welding, cutting and grinding | B10: =UTPALAA!D181 -> 0.71428571 | C10: =AVERAGE(B10) -> 0.71428571 | O10: Welding, cutting and grinding | P10: 0.86 | Q10: 0.86 | R10: 0.84 | S10: 0.87
A11: Vehicles, Earth movers & Lifting Equipment | B11: =UTPALAA!D182 -> 0.52272727 | C11: =AVERAGE(B11) -> 0.52272727 | O11: Vehicles, Earth movers & Lifting Equipment | P11: 0.84 | Q11: 0.85 | R11: 0.83 | S11: 0.84
A12: Fire Prevention/ Protection | B12: =UTPALAA!D183 -> 0.65625 | C12: =AVERAGE(B12) -> 0.65625 | O12: Fire Prevention/ Protection | P12: 0.88 | Q12: 0.89 | R12: 0.87 | S12: 0.85
A13: First Aid & Medical Facilities | B13: =UTPALAA!D184 -> 0.83333333 | C13: =AVERAGE(B13) -> 0.83333333 | O13: First Aid & Medical Facilities | P13: 0.89 | Q13: 0.86 | R13: 0.8 | S13: 0.89
A14: Welfare Facilities and labour accomodation | B14: =UTPALAA!D185 -> 0.96428571 | C14: =AVERAGE(B14) -> 0.96428571 | O14: Welfare Facilities and labour accomodation | P14: 0.89 | Q14: 0.88 | R14: 0.93 | S14: 0.89
A15: Environment Aspects | B15: =UTPALAA!D186 -> 0.5 | C15: =AVERAGE(B15) -> 0.5 | O15: Environment Aspects | P15: 0.88 | Q15: 0.88 | R15: 0.83 | S15: 0.85
A16: Piling Work | B16: =UTPALAA!D187 -> NA | C16: =AVERAGE(B16) -> #DIV/0! | O16: Piling Work | P16: 0 | Q16: 0 | R16: 0 | S16: 0.75
... A18: Hand tools (manual and power driven) | B18: =UTPALAA!D189 -> 0.875 | C18: =AVERAGE(B18) -> 0.875 | O18: Hand tools (manual and power driven) | P18: 0.84 | Q18: 0.91 | R18: 0.91 | S18: 0.88
B19: =AVERAGE(B5:B18) -> 0.67501649 | C19: =AVERAGE(B19) -> 0.67501649
B20: =UTPALAA!C171 -> 0.67030361 | C20: =AVERAGE(B20:B20) -> 0.67030361
